<?xml version='1.0'?>
<sdf version='1.6'>

    <model name="conveyor_belt">

      <model name="conveyor_belt_fixed">
        <static>true</static>
        <link name="link">
            <!--
          <visual name='visual_1'>
              <geometry>
              <mesh>
                <uri>model://conveyor_belt/meshes/conveyorbelt_3u.dae</uri>
                <scale>1 1 1</scale>
              </mesh>
            </geometry>
            <cast_shadows>1</cast_shadows>
            <transparency>1.0</transparency>
          </visual>
          -->
        </link>
      </model>

      <model name="conveyor_belt_moving">
        <static>false</static>
        <link name="belt">
          <pose>4.5 0 0.88122 0 0 0</pose>
          <inertial>
            <inertia>
              <ixx>3.60095210083</ixx>
              <ixy>0</ixy>
              <ixz>0</ixz>
              <iyy>819.362638413</iyy>
              <iyz>0</iyz>
              <izz>822.903590514</izz>
            </inertia>
            <mass>100</mass>
          </inertial>
            <!--
          <visual name="belt_visual">
            <geometry>
              <box>
                <size>9.91564 0.65461 0.06</size>
              </box>
            </geometry>
          </visual>
            -->
          <collision name="belt_collision">
            <max_contacts>30</max_contacts>
            <geometry>
              <box>
                <size>9.91564 0.65461 0.06</size>
              </box>
            </geometry>
            <surface>
              <friction>
                <ode>
                  <mu>1.0</mu>
                  <mu2>0.1</mu2>
                </ode>
                <torsional>
                  <coefficient>1000.0</coefficient>
                  <patch_radius>0.1</patch_radius>
                </torsional>
              </friction>
            </surface>
          </collision>
        </link>
      </model>

      <joint name="belt_joint" type="prismatic">
        <parent>conveyor_belt_fixed::link</parent>
        <child>conveyor_belt_moving::belt</child>
        <axis>
          <xyz>1 0 0</xyz>
          <limit>
            <lower>0</lower>
            <upper>1.0</upper>
          </limit>
        </axis>
      </joint>

      <plugin name="conveyor_belt_plugin" filename="libROSConveyorBeltPlugin.so">
        <robot_namespace>/conveyor</robot_namespace>
        <population_rate_modifier_topic>/conveyor/population/rate_modifier</population_rate_modifier_topic>
        <link>conveyor_belt::conveyor_belt_moving::belt</link>
        <power>0</power>
      </plugin>
    </model>

</sdf>
